Workbook

Sheet Instructions
B2: Igbo Translation Model — Scoresheet Instructions
B4: How to use this workbook
B5: Go to the "Scores" tab. Each row is one test sentence with the model's Igbo translation already filled in.
B6: For each row, enter a score from 1–5 in the Accuracy and Fluency columns (yellow cells).
B7: Add any notes in the Comments column — e.g. wrong word choice, awkward phrasing, missed negation, etc.
B9: Scoring guide — Accuracy (does it mean the same thing as the English?)
B10: 5 = Fully correct meaning
B11: 4 = Correct meaning, very minor issue
B12: 3 = Mostly correct, one clear error
B13: 2 = Partially correct, meaning is distorted
B14: 1 = Wrong or nonsensical
B16: Scoring guide — Fluency (does it read naturally in Igbo?)
... B25: The Summary tab automatically calculates averages per category and type as you enter scores.

Sheet Scores
A1: No. | B1: Category | C1: Type | D1: English Sentence | E1: Igbo Translation | F1: Status | G1: Accuracy (1-5) | H1: Fluency (1-5) | I1: Comments
A2: 1 | B2: Greeting | C2: Question | D2: Good morning, how are you today? | E2: [FAILED: HTTPConnectionPool(host='localhost', port=5002): Read timed out. (read timeout=120)] | F2: FAILED
A3: 2 | B3: Question | C3: Question | D3: What is your name? | E3: [FAILED: HTTPConnectionPool(host='localhost', port=5002): Read timed out. (read timeout=120)] | F3: FAILED
A4: 3 | B4: Negation | C4: Question | D4: Do you understand what I am saying? | E4: Ị̀ ghọtara ihe m na-ekwu? | F4: OK
A5: 4 | B5: Request | C5: Question | D5: Can you please close the door? | E5: Biko, ị̀ pụrụ imechi ụzọ ahụ? | F5: OK
A6: 5 | B6: Question | C6: Question | D6: Where is the nearest hospital? | E6: Olee ụlọ ọgwụ kacha nso? | F6: OK
A7: 6 | B7: Shopping | C7: Question | D7: How much does this bag cost? | E7: Ego ole ka akpa a na-efu? | F7: OK
A8: 7 | B8: Weather | C8: Question | D8: Is it raining outside? | E8: Mmiri ọ̀ na-ezo n'èzí? | F8: OK
A9: 8 | B9: Location | C9: Question | D9: Where is the bathroom? | E9: Ebee ka ụlọ ịsa ahụ dị? | F9: OK
A10: 9 | B10: Time | C10: Question | D10: What time is it currently? | E10: Oge ole ka ọ bụ ugbu a? | F10: OK
A11: 10 | B11: Language | C11: Question | D11: Do you speak English fluently? | E11: Ị̀ na-asụ Bekee nke ọma? | F11: OK
A12: 11 | B12: Culture | C12: Question | D12: Why should we respect our elders in the community? | E12: Gịnị mere anyị ji kwesị ịna-akwanyere ndị okenye ùgwù? | F12: OK
A13: 12 | B13: Formal/Complex | C13: Question | D13: Can you explain why, despite the government's promise to build more schools, many rural communities still lack access to quality education? | E13: Ị̀ pụrụ ịkọwa ihe mere, n'agbanyeghị nkwa gọọmenti kwere iwulite ụlọ akwụkwọ ndị ọzọ, ọtụtụ obodo ndị dị n'ime ime obodo ka na-enweghị ohere inweta agụmakwụkwọ dị mma? | F13: OK
... A101: 100 | B101: Complex Systems/Climate Modeling | C101: Question | D101: Given the highly non-linear feedback loops inherent in global climate systems, such as the thawing of Arctic permafrost releasing massive reservoirs of methane, how can scientists reduce uncertainty in long-range temperature projections to provide policy-makers with actionable, localized adaptation timelines? What are the mathematical limits of predicting sudden, catastrophic tipping points in these complex systems? | E101: N'iburu n'uche usoro nzaghachi na-abụghị nke dị n'usoro nke usoro ihu igwe zuru ụwa ọnụ, dị ka ịgbanye permafrost Arctic na-ewepụta nnukwu ihe nchekwa nke methane, olee otu ndị ọkà mmụta sayensị ga-esi belata ejighị n'aka na amụma okpomọkụ dị ogologo iji nye ndị na-eme iwu usoro nhazi oge eji eme ihe, nke dị n'ógbè? Gịnị bụ njedebe mgbakọ na mwepụ nke ịkọ amụma mberede, ọdachi na-akpata nrịba n'ọnọdụ dị mgbagwoju anya na usoro ndị a? | F101: OK
D103: Average (scored rows only) | G103: =IFERROR(AVERAGE(G2:G101),"") | H103: =IFERROR(AVERAGE(H2:H101),"")

Sheet Summary
B2: Summary by Category
B4: No. | C4: Category | D4: Count | E4: Avg Accuracy | F4: Avg Fluency
B5: 1 | C5: Administration | D5: =COUNTIFS(Scores!B:B,"Administration",Scores!G:G,"<>") -> 0 | E5: =IFERROR(AVERAGEIFS(Scores!G:G,Scores!B:B,"Administration"),"") | F5: =IFERROR(AVERAGEIFS(Scores!H:H,Scores!B:B,"Administration"),"")
B6: 2 | C6: Agri-tech/Climate | D6: =COUNTIFS(Scores!B:B,"Agri-tech/Climate",Scores!G:G,"<>") -> 0 | E6: =IFERROR(AVERAGEIFS(Scores!G:G,Scores!B:B,"Agri-tech/Climate"),"") | F6: =IFERROR(AVERAGEIFS(Scores!H:H,Scores!B:B,"Agri-tech/Climate"),"")
B7: 3 | C7: Agricultural Biotechnology | D7: =COUNTIFS(Scores!B:B,"Agricultural Biotechnology",Scores!G:G,"<>") -> 0 | E7: =IFERROR(AVERAGEIFS(Scores!G:G,Scores!B:B,"Agricultural Biotechnology"),"") | F7: =IFERROR(AVERAGEIFS(Scores!H:H,Scores!B:B,"Agricultural Biotechnology"),"")
B8: 4 | C8: Agriculture | D8: =COUNTIFS(Scores!B:B,"Agriculture",Scores!G:G,"<>") -> 0 | E8: =IFERROR(AVERAGEIFS(Scores!G:G,Scores!B:B,"Agriculture"),"") | F8: =IFERROR(AVERAGEIFS(Scores!H:H,Scores!B:B,"Agriculture"),"")
B9: 5 | C9: Artificial Intelligence/Creativity | D9: =COUNTIFS(Scores!B:B,"Artificial Intelligence/Creativity",Scores!G:G,"<>") -> 0 | E9: =IFERROR(AVERAGEIFS(Scores!G:G,Scores!B:B,"Artificial Intelligence/Creativity"),"") | F9: =IFERROR(AVERAGEIFS(Scores!H:H,Scores!B:B,"Artificial Intelligence/Creativity"),"")
B10: 6 | C10: Astrophysics/Space Law | D10: =COUNTIFS(Scores!B:B,"Astrophysics/Space Law",Scores!G:G,"<>") -> 0 | E10: =IFERROR(AVERAGEIFS(Scores!G:G,Scores!B:B,"Astrophysics/Space Law"),"") | F10: =IFERROR(AVERAGEIFS(Scores!H:H,Scores!B:B,"Astrophysics/Space Law"),"")
B11: 7 | C11: Behavioral Finance | D11: =COUNTIFS(Scores!B:B,"Behavioral Finance",Scores!G:G,"<>") -> 0 | E11: =IFERROR(AVERAGEIFS(Scores!G:G,Scores!B:B,"Behavioral Finance"),"") | F11: =IFERROR(AVERAGEIFS(Scores!H:H,Scores!B:B,"Behavioral Finance"),"")
B12: 8 | C12: Biomedical Ethics | D12: =COUNTIFS(Scores!B:B,"Biomedical Ethics",Scores!G:G,"<>") -> 0 | E12: =IFERROR(AVERAGEIFS(Scores!G:G,Scores!B:B,"Biomedical Ethics"),"") | F12: =IFERROR(AVERAGEIFS(Scores!H:H,Scores!B:B,"Biomedical Ethics"),"")
B13: 9 | C13: Biosafety/Agriculture Policy | D13: =COUNTIFS(Scores!B:B,"Biosafety/Agriculture Policy",Scores!G:G,"<>") -> 0 | E13: =IFERROR(AVERAGEIFS(Scores!G:G,Scores!B:B,"Biosafety/Agriculture Policy"),"") | F13: =IFERROR(AVERAGEIFS(Scores!H:H,Scores!B:B,"Biosafety/Agriculture Policy"),"")
B14: 10 | C14: Civics | D14: =COUNTIFS(Scores!B:B,"Civics",Scores!G:G,"<>") -> 0 | E14: =IFERROR(AVERAGEIFS(Scores!G:G,Scores!B:B,"Civics"),"") | F14: =IFERROR(AVERAGEIFS(Scores!H:H,Scores!B:B,"Civics"),"")
B15: 11 | C15: Clarification | D15: =COUNTIFS(Scores!B:B,"Clarification",Scores!G:G,"<>") -> 0 | E15: =IFERROR(AVERAGEIFS(Scores!G:G,Scores!B:B,"Clarification"),"") | F15: =IFERROR(AVERAGEIFS(Scores!H:H,Scores!B:B,"Clarification"),"")
B16: 12 | C16: Cognitive Psychology | D16: =COUNTIFS(Scores!B:B,"Cognitive Psychology",Scores!G:G,"<>") -> 0 | E16: =IFERROR(AVERAGEIFS(Scores!G:G,Scores!B:B,"Cognitive Psychology"),"") | F16: =IFERROR(AVERAGEIFS(Scores!H:H,Scores!B:B,"Cognitive Psychology"),"")
B17: 13 | C17: Cognitive Science | D17: =COUNTIFS(Scores!B:B,"Cognitive Science",Scores!G:G,"<>") -> 0 | E17: =IFERROR(AVERAGEIFS(Scores!G:G,Scores!B:B,"Cognitive Science"),"") | F17: =IFERROR(AVERAGEIFS(Scores!H:H,Scores!B:B,"Cognitive Science"),"")
B18: 14 | C18: Communication | D18: =COUNTIFS(Scores!B:B,"Communication",Scores!G:G,"<>") -> 0 | E18: =IFERROR(AVERAGEIFS(Scores!G:G,Scores!B:B,"Communication"),"") | F18: =IFERROR(AVERAGEIFS(Scores!H:H,Scores!B:B,"Communication"),"")
B19: 15 | C19: Complex Systems/Climate Modeling | D19: =COUNTIFS(Scores!B:B,"Complex Systems/Climate Modeling",Scores!G:G,"<>") -> 0 | E19: =IFERROR(AVERAGEIFS(Scores!G:G,Scores!B:B,"Complex Systems/Climate Modeling"),"") | F19: =IFERROR(AVERAGEIFS(Scores!H:H,Scores!B:B,"Complex Systems/Climate Modeling"),"")
B20: 16 | C20: Complex/Compound | D20: =COUNTIFS(Scores!B:B,"Complex/Compound",Scores!G:G,"<>") -> 0 | E20: =IFERROR(AVERAGEIFS(Scores!G:G,Scores!B:B,"Complex/Compound"),"") | F20: =IFERROR(AVERAGEIFS(Scores!H:H,Scores!B:B,"Complex/Compound"),"")
B21: 17 | C21: Concession/Complex | D21: =COUNTIFS(Scores!B:B,"Concession/Complex",Scores!G:G,"<>") -> 0 | E21: =IFERROR(AVERAGEIFS(Scores!G:G,Scores!B:B,"Concession/Complex"),"") | F21: =IFERROR(AVERAGEIFS(Scores!H:H,Scores!B:B,"Concession/Complex"),"")
B22: 18 | C22: Conditional/Complex | D22: =COUNTIFS(Scores!B:B,"Conditional/Complex",Scores!G:G,"<>") -> 0 | E22: =IFERROR(AVERAGEIFS(Scores!G:G,Scores!B:B,"Conditional/Complex"),"") | F22: =IFERROR(AVERAGEIFS(Scores!H:H,Scores!B:B,"Conditional/Complex"),"")
B23: 19 | C23: Constitutional Law | D23: =COUNTIFS(Scores!B:B,"Constitutional Law",Scores!G:G,"<>") -> 0 | E23: =IFERROR(AVERAGEIFS(Scores!G:G,Scores!B:B,"Constitutional Law"),"") | F23: =IFERROR(AVERAGEIFS(Scores!H:H,Scores!B:B,"Constitutional Law"),"")
B24: 20 | C24: Corporate Crisis Management | D24: =COUNTIFS(Scores!B:B,"Corporate Crisis Management",Scores!G:G,"<>") -> 0 | E24: =IFERROR(AVERAGEIFS(Scores!G:G,Scores!B:B,"Corporate Crisis Management"),"") | F24: =IFERROR(AVERAGEIFS(Scores!H:H,Scores!B:B,"Corporate Crisis Management"),"")
B25: 21 | C25: Corporate Governance/AI Ethics | D25: =COUNTIFS(Scores!B:B,"Corporate Governance/AI Ethics",Scores!G:G,"<>") -> 0 | E25: =IFERROR(AVERAGEIFS(Scores!G:G,Scores!B:B,"Corporate Governance/AI Ethics"),"") | F25: =IFERROR(AVERAGEIFS(Scores!H:H,Scores!B:B,"Corporate Governance/AI Ethics"),"")
B26: 22 | C26: Corporate Tax/Global Trade | D26: =COUNTIFS(Scores!B:B,"Corporate Tax/Global Trade",Scores!G:G,"<>") -> 0 | E26: =IFERROR(AVERAGEIFS(Scores!G:G,Scores!B:B,"Corporate Tax/Global Trade"),"") | F26: =IFERROR(AVERAGEIFS(Scores!H:H,Scores!B:B,"Corporate Tax/Global Trade"),"")
B27: 23 | C27: Correlative/Complex | D27: =COUNTIFS(Scores!B:B,"Correlative/Complex",Scores!G:G,"<>") -> 0 | E27: =IFERROR(AVERAGEIFS(Scores!G:G,Scores!B:B,"Correlative/Complex"),"") | F27: =IFERROR(AVERAGEIFS(Scores!H:H,Scores!B:B,"Correlative/Complex"),"")
B28: 24 | C28: Culture | D28: =COUNTIFS(Scores!B:B,"Culture",Scores!G:G,"<>") -> 0 | E28: =IFERROR(AVERAGEIFS(Scores!G:G,Scores!B:B,"Culture"),"") | F28: =IFERROR(AVERAGEIFS(Scores!H:H,Scores!B:B,"Culture"),"")
B29: 25 | C29: Customer Service | D29: =COUNTIFS(Scores!B:B,"Customer Service",Scores!G:G,"<>") -> 0 | E29: =IFERROR(AVERAGEIFS(Scores!G:G,Scores!B:B,"Customer Service"),"") | F29: =IFERROR(AVERAGEIFS(Scores!H:H,Scores!B:B,"Customer Service"),"")
B30: 26 | C30: Cybersecurity/National Defense | D30: =COUNTIFS(Scores!B:B,"Cybersecurity/National Defense",Scores!G:G,"<>") -> 0 | E30: =IFERROR(AVERAGEIFS(Scores!G:G,Scores!B:B,"Cybersecurity/National Defense"),"") | F30: =IFERROR(AVERAGEIFS(Scores!H:H,Scores!B:B,"Cybersecurity/National Defense"),"")
B31: 27 | C31: Distributed Systems | D31: =COUNTIFS(Scores!B:B,"Distributed Systems",Scores!G:G,"<>") -> 0 | E31: =IFERROR(AVERAGEIFS(Scores!G:G,Scores!B:B,"Distributed Systems"),"") | F31: =IFERROR(AVERAGEIFS(Scores!H:H,Scores!B:B,"Distributed Systems"),"")
B32: 28 | C32: ESG Governance | D32: =COUNTIFS(Scores!B:B,"ESG Governance",Scores!G:G,"<>") -> 0 | E32: =IFERROR(AVERAGEIFS(Scores!G:G,Scores!B:B,"ESG Governance"),"") | F32: =IFERROR(AVERAGEIFS(Scores!H:H,Scores!B:B,"ESG Governance"),"")
B33: 29 | C33: Economic History | D33: =COUNTIFS(Scores!B:B,"Economic History",Scores!G:G,"<>") -> 0 | E33: =IFERROR(AVERAGEIFS(Scores!G:G,Scores!B:B,"Economic History"),"") | F33: =IFERROR(AVERAGEIFS(Scores!H:H,Scores!B:B,"Economic History"),"")
B34: 30 | C34: Economics | D34: =COUNTIFS(Scores!B:B,"Economics",Scores!G:G,"<>") -> 0 | E34: =IFERROR(AVERAGEIFS(Scores!G:G,Scores!B:B,"Economics"),"") | F34: =IFERROR(AVERAGEIFS(Scores!H:H,Scores!B:B,"Economics"),"")
B35: 31 | C35: Education | D35: =COUNTIFS(Scores!B:B,"Education",Scores!G:G,"<>") -> 0 | E35: =IFERROR(AVERAGEIFS(Scores!G:G,Scores!B:B,"Education"),"") | F35: =IFERROR(AVERAGEIFS(Scores!H:H,Scores!B:B,"Education"),"")
B36: 32 | C36: Employment | D36: =COUNTIFS(Scores!B:B,"Employment",Scores!G:G,"<>") -> 0 | E36: =IFERROR(AVERAGEIFS(Scores!G:G,Scores!B:B,"Employment"),"") | F36: =IFERROR(AVERAGEIFS(Scores!H:H,Scores!B:B,"Employment"),"")
B37: 33 | C37: Environment | D37: =COUNTIFS(Scores!B:B,"Environment",Scores!G:G,"<>") -> 0 | E37: =IFERROR(AVERAGEIFS(Scores!G:G,Scores!B:B,"Environment"),"") | F37: =IFERROR(AVERAGEIFS(Scores!H:H,Scores!B:B,"Environment"),"")
B38: 34 | C38: Environmental Architecture | D38: =COUNTIFS(Scores!B:B,"Environmental Architecture",Scores!G:G,"<>") -> 0 | E38: =IFERROR(AVERAGEIFS(Scores!G:G,Scores!B:B,"Environmental Architecture"),"") | F38: =IFERROR(AVERAGEIFS(Scores!H:H,Scores!B:B,"Environmental Architecture"),"")
B39: 35 | C39: Environmental Law | D39: =COUNTIFS(Scores!B:B,"Environmental Law",Scores!G:G,"<>") -> 0 | E39: =IFERROR(AVERAGEIFS(Scores!G:G,Scores!B:B,"Environmental Law"),"") | F39: =IFERROR(AVERAGEIFS(Scores!H:H,Scores!B:B,"Environmental Law"),"")
B40: 36 | C40: Epidemiology/Global Policy | D40: =COUNTIFS(Scores!B:B,"Epidemiology/Global Policy",Scores!G:G,"<>") -> 0 | E40: =IFERROR(AVERAGEIFS(Scores!G:G,Scores!B:B,"Epidemiology/Global Policy"),"") | F40: =IFERROR(AVERAGEIFS(Scores!H:H,Scores!B:B,"Epidemiology/Global Policy"),"")
B41: 37 | C41: Ethics/Algorithmic AI | D41: =COUNTIFS(Scores!B:B,"Ethics/Algorithmic AI",Scores!G:G,"<>") -> 0 | E41: =IFERROR(AVERAGEIFS(Scores!G:G,Scores!B:B,"Ethics/Algorithmic AI"),"") | F41: =IFERROR(AVERAGEIFS(Scores!H:H,Scores!B:B,"Ethics/Algorithmic AI"),"")
B42: 38 | C42: Event Planning | D42: =COUNTIFS(Scores!B:B,"Event Planning",Scores!G:G,"<>") -> 0 | E42: =IFERROR(AVERAGEIFS(Scores!G:G,Scores!B:B,"Event Planning"),"") | F42: =IFERROR(AVERAGEIFS(Scores!H:H,Scores!B:B,"Event Planning"),"")
...
